Workbook

Sheet BDD
P2: Bail | X2: Financement | AM2: Detention capital € | AQ2: VALORISATION | AS2: Démembrement
A3: SCI | B3: Date d'aquisition | C3: Code postal | D3: Ville | E3: adresse | F3: N°de lot | G3: Destination | H3: surface terrain m² | I3: Surfaces privatives | J3: Usage | K3: Copro | L3: Prix d'acquisition | M3: Description avant travaux | N3: Section cadastre | O3: Type de bail | P3: Locataire | Q3: date de début | R3: date de fin | S3: Loyer annuel de départ | T3: soumis à TVA | U3: indice revalorisation loyers | V3: Loyer annuel actuel HC (07/2025) | W3: Surface louée en m² | X3: Quote part prix d'achat | Y3: Quote part non financé/apport | Z3: TOTAL Emprunts | AA3: VO | AB3: VNC | AC3: Quote part Emprunt | AD3: Quote part Emprunt reste à payer à fin 2025 | AE3: Banques | AF3: Garantie | AG3: Durée | AH3: Date de fin | AI3: Taux d'intérêt | AJ3: Taux d'assurance | AK3: Taux IRA | AL3: Comptes courants débiteurs | AM3: Damien | AN3: Sebastien | AO3: HIO | AP3: AXORIEL | AQ3: sur base 7% de renta | AR3: prix m² | AS3: oui/non
A4: 34 RUE HAUTE | B4: 44558 | C4: 95170 | D4: DEUIL LA BARRE | E4: 34 RUE HAUTE | G4: Crèche | H4: 1265 | K4: non | L4: 380000 | M4: une maison à usage d'habitation et son terrain | N4: AE273;AE1086;AE1177 | O4: commercial | P4: LPC LE LAC | Q4: 44562 | R4: 47848 | S4: 87000 | T4: non | U4: ILC | W4: 395 | X4: =$L$4*W4/SUM($W$4:$W$9) -> 201964.48 | Y4: =33500/SUM($X$4:$X$9)*X4 -> 17804.763 | Z4: =1924000+350000 -> 2274000 | AA4: 2390000 | AB4: 70000 | AC4: =$Z$4/SUM($W$4:$W$9)*W4 -> 1208598 | AD4: =(305557+1175369+308929)/SUM($AC$4:$AC$9)*AC4 -> 951281.92 | AE4: SG et CE | AF4: sur SG caution HIO et AXORIEL sur CE hypothèque et Caution SAS | AG4: 15 CE et 7 SG | AH4: 49836 | AI4: 1,35% CE et 3,53% SG | AJ4: non trouvé | AK4: sur emprunt SG voir formule (environ 6 mois d'intérêt) | AM4: 0.0001 | AN4: 0.0001 | AO4: 0.4999 | AP4: 0.4999
A5: 34 RUE HAUTE | B5: 44558 | C5: 95170 | D5: DEUIL LA BARRE | E5: 34 RUE HAUTE | G5: Ecole | H5: 1265 | K5: non | M5: une maison à usage d'habitation et son terrain | N5: AE273;AE1086;AE1177 | O5: professionnel | P5: CESAP | Q5: 45412 | R5: 48698 | S5: 30600 | T5: non | U5: ICC 4T2023 = 2162 | V5: =S5/2162*2146 -> 30373.543 | W5: 174 | X5: =$L$4*W5/SUM($W$4:$W$9) -> 88966.631 | Y5: =33500/SUM($X$4:$X$9)*X5 -> 7843.1109 | AC5: =$Z$4/SUM($W$4:$W$9)*W5 -> 532395.05 | AD5: =(305557+1175369+308929)/SUM($AC$4:$AC$9)*AC5 -> 419045.71 | AM5: 0.0001 | AN5: 0.0001 | AO5: 0.4999 | AP5: 0.4999
A6: 34 RUE HAUTE | B6: 44558 | C6: 95170 | D6: DEUIL LA BARRE | E6: 34 RUE HAUTE | G6: Logements 1 appartement avec terrasse et jardin RDC | H6: 1265 | K6: non | M6: une maison à usage d'habitation et son terrain | N6: AE273;AE1086;AE1177 | O6: logement | P6: M. BONHOMME | Q6: 45261 | R6: 47452 | S6: =895*12 -> 10740 | T6: non | U6: IRL 3T2023 = 141,03 | W6: 43.4 | X6: =$L$4*W6/SUM($W$4:$W$9) -> 22190.527 | Y6: =33500/SUM($X$4:$X$9)*X6 -> 1956.2702 | AC6: =$Z$4/SUM($W$4:$W$9)*W6 -> 132792.79 | AD6: =(305557+1175369+308929)/SUM($AC$4:$AC$9)*AC6 -> 104520.6 | AM6: 0.0001 | AN6: 0.0001 | AO6: 0.4999 | AP6: 0.4999
A7: 34 RUE HAUTE | B7: 44558 | C7: 95170 | D7: DEUIL LA BARRE | E7: 34 RUE HAUTE | G7: Logements 2 appartement RDC | H7: 1265 | K7: non | M7: une maison à usage d'habitation et son terrain | N7: AE273;AE1086;AE1177 | O7: logement | P7: M. LEPAGE | Q7: 45234 | R7: 47425 | S7: =590*12 -> 7080 | T7: non | U7: IRL 3T2023 = 141,03 | W7: 27.7 | X7: =$L$4*W7/SUM($W$4:$W$9) -> 14163.079 | Y7: =33500/SUM($X$4:$X$9)*X7 -> 1248.5872 | AC7: =$Z$4/SUM($W$4:$W$9)*W7 -> 84754.844 | AD7: =(305557+1175369+308929)/SUM($AC$4:$AC$9)*AC7 -> 66710.15 | AM7: 0.0001 | AN7: 0.0001 | AO7: 0.4999 | AP7: 0.4999
A8: 34 RUE HAUTE | B8: 44558 | C8: 95170 | D8: DEUIL LA BARRE | E8: 34 RUE HAUTE | G8: Logements 3 1er étage à droite | H8: 1265 | K8: non | M8: une maison à usage d'habitation et son terrain | N8: AE273;AE1086;AE1177 | O8: logement | P8: Mme CHERIF | Q8: 45428 | R8: 47618 | S8: =870*12 -> 10440 | T8: non | U8: IRL 1T2024 = 143,46 | W8: 45.4 | X8: =$L$4*W8/SUM($W$4:$W$9) -> 23213.132 | Y8: =33500/SUM($X$4:$X$9)*X8 -> 2046.4209 | AC8: =$Z$4/SUM($W$4:$W$9)*W8 -> 138912.27 | AD8: =(305557+1175369+308929)/SUM($AC$4:$AC$9)*AC8 -> 109337.21 | AM8: 0.0001 | AN8: 0.0001 | AO8: 0.4999 | AP8: 0.4999
A9: 34 RUE HAUTE | B9: 44558 | C9: 95170 | D9: DEUIL LA BARRE | E9: 34 RUE HAUTE | G9: Logements 4 1er étage à gauche | H9: 1265 | K9: non | M9: une maison à usage d'habitation et son terrain | N9: AE273;AE1086;AE1177 | O9: logement | P9: M. SAIDI | Q9: 45444 | R9: 47634 | S9: =1065*12 -> 12780 | T9: non | U9: IRL 1T2024 = 143,46 | W9: 57.7 | X9: =$L$4*W9/SUM($W$4:$W$9) -> 29502.153 | Y9: =33500/SUM($X$4:$X$9)*X9 -> 2600.8477 | AC9: =$Z$4/SUM($W$4:$W$9)*W9 -> 176547.09 | AD9: =(305557+1175369+308929)/SUM($AC$4:$AC$9)*AC9 -> 138959.41 | AM9: 0.0001 | AN9: 0.0001 | AO9: 0.4999 | AP9: 0.4999
A10: LEGRAND | B10: 42965 | C10: 93160 | D10: NOISY LE GRAND | E10: 12 BD DU MONT D'EST | G10: Crèche Noisy | H10: =5050+6587 -> 11637 | I10: 231.1 | J10: bureaux | K10: oui | L10: 250000 | M10: immeuble de 5 étages avec parking jardin et cour | N10: BO168 et BO163 | O10: commercial | P10: LPC LE GRAND | Q10: 43191 | R10: 46843 | S10: 31284 | T10: non | U10: ILC 2T2017 = 110 | V10: =9720.79*4 -> 38883.16 | W10: 231.1 | X10: 250000 | Y10: =3893.7+16283 -> 20176.7 | Z10: 250000 | AC10: =Z10 -> 250000 | AD10: 5217 | AE10: BNP | AF10: Cautionnement de la SAS + privilège de prêteur de deniers | AG10: 8 | AH10: 46071 | AI10: 0.0134 | AJ10: non trouvé | AK10: 0.005 | AM10: 0.5 | AN10: 0.5 | AO10: 0 | AP10: 0 | AS10: oui usufruit SAS
A11: LEGRAND | B11: 43284 | C11: 92330 | D11: SCEAUX | E11: 146/148 RUE HOUDAN | G11: Crèche Sceaux | H11: 807 | I11: 192.6 | J11: commercial | K11: oui | L11: 780000 | M11: immeuble | N11: E174 | O11: commercial | P11: LPC SCEAUX | Q11: 43282 | R11: 46934 | S11: 62000 | T11: non | U11: ILC 1T2018 = 127,22 | V11: =17723.51*4 -> 70894.04 | W11: 192 | X11: 780000 | Y11: 114430 | Z11: 780000 | AC11: =Z11 -> 780000 | AD11: 421889 | AE11: SG | AF11: Cautionnement de la SAS (546k€) | AG11: =180/12 -> 15 | AH11: 48763 | AI11: 0.0189 | AJ11: non trouvé | AK11: page 70 à priori plus rien à partir 03/01/2026 | AM11: 0.5 | AN11: 0.5 | AO11: 0 | AP11: 0 | AS11: oui usufruit SAS
A12: ARMEE ORIENT | B12: 44751 | C12: 78680 | D12: EPONE | E12: Route de Velannes | G12: Crèche Epone | I12: 398.1 | K12: non | L12: 352908 | M12: ensemble immobilier formé par un local d'activité et son jardin | N12: J1451-1641-1473-1477-1478-1482-1481-1486-1480 | O12: commercial | P12: LPC MEDERIC | Q12: 44927 | R12: 49340 | S12: 59090 | T12: non | U12: ILC | V12: =15220*4 -> 60880 | W12: 311 | X12: =L12 -> 352908 | Z12: =AC12 -> 377612 | AC12: 377612 | AD12: 309356 | AE12: LCL | AF12: Affectation hypothécaire du bien immobilier | AG12: 15 | AH12: 50228 | AI12: 0.018 | AJ12: 0.00087 | AM12: 0.0001 | AN12: 0.0001 | AO12: 0.4999 | AP12: 0.4999
A13: ARMEE ORIENT | B13: 44749 | C13: 06300 | D13: NICE | E13: 8 rue Armée D'Orient | G13: Crèche Nice | K13: oui | L13: 665000 | O13: commercial | P13: LPC FREJUS | Q13: 44927 | R13: 48244 | S13: 55000 | T13: non | U13: ILC | V13: =15012.39*4 -> 60049.56 | W13: 201 | X13: =L13 -> 665000 | Z13: 665000 | AC13: =Z13 -> 665000 | AD13: 553110 | AE13: CA | AF13: Hypothèque conventionnelle + Cautionnements solidaires HIO et AXORIEL | AG13: 15 | AH13: 50469 | AI13: 0.014 | AJ13: non trouvé | AK13: 2 mois d'intérêt sur le capital remboursé ou formule | AM13: 0.0001 | AN13: 0.0001 | AO13: 0.4999 | AP13: 0.4999
A14: CHENNEVIERES | B14: Vefa le 01/07/2022 | C14: 94430 | D14: CHENNEVIERES SUR MARNE | E14: 49 rue Aristide Briand | G14: Crèche Chennevières | I14: 206.34 | L14: 734000 | O14: commercial | P14: LPC VAL DE MARNE | Q14: 45170 | R14: 48822 | S14: 75240 | T14: non | U14: ILC | V14: =19672.44*4 -> 78689.76 | W14: 206 | Z14: 734000 | AC14: =Z14 -> 734000 | AD14: 685859 | AE14: LCL | AF14: Affectation hypothécaire du bien immobilier | AG14: 15 | AH14: 50614 | AI14: 0.046 | AJ14: non trouvé | AK14: 1 semestre d'intérêts au taux conventionnel sur le montant remboursé | AM14: 0.0001 | AN14: 0.0001 | AO14: 0.4999 | AP14: 0.4999
A15: CHENNEVIERES | B15: 45055 | C15: 94140 | D15: ALFORTVILLE | E15: 105 rue Etienne Dolet | G15: Crèche Alforville | I15: 311.4 | K15: oui | L15: 840000 | M15: Local commercial | O15: commercial | P15: LPC VAL DE MARNE | Q15: 45292 | R15: 45291 | S15: 86100 | T15: non | U15: ILC | V15: =22177.22*4 -> 88708.88 | W15: 311.4 | X15: =L15 -> 840000 | Y15: =899210.68+6061.35-X15 -> 65272.03 | Z15: 840000 | AC15: =Z15 -> 840000 | AD15: 792257 | AE15: SG | AF15: IPPD et hypothèque. | AG15: 15 | AH15: 50724 | AI15: 0.0453 | AJ15: non trouvé | AK15: voir formule (environ 6 mois d'intérêt) | AM15: 0.0001 | AN15: 0.0001 | AO15: 0.4999 | AP15: 0.4999
A16: TAVERNY | B16: 44889 | C16: 95150 | D16: TAVERNY | E16: 3 rue des Ecoles | G16: Crèche Taverny | I16: 417.97 | K16: oui | L16: 1337730.6 | M16: ensemble immobilier | P16: LPC TAVERNY | Q16: 46266 | S16: 67000 | X16: =L16 -> 1337730.6 | Z16: 1408923 | AC16: =Z16 -> 1408923 | AD16: 1408923 | AE16: CE | AF16: Affectation hypothécaire du bien immobilier | AG16: 20 | AH16: 53332 | AI16: 0.0404 | AJ16: 0.00327 | AK16: non trouvé | AM16: 0.0001 | AN16: 0.0001 | AO16: 0.4999 | AP16: 0.4999
A17: GENERAL JULES BRIMONT | B17: 45128 | C17: 78400 | D17: CHATOU | E17: 32 avenue de Brimont | G17: Crèche Chatou | I17: 387.83 | K17: oui | L17: 1200000 | M17: Local à usage d'activité | N17: AR39-42 | O17: commercial | P17: LPC YVELINES | Q17: 45170 | R17: 48457 | S17: 84000 | T17: non | U17: ILC | V17: =21962.85*4 -> 87851.4 | W17: 258.7 | X17: =$L$17/SUM($W$17:$W$22)*W17 -> 897744.36 | Y17: =108673/(SUM($X$17:$X$22))*X17 -> 81300.477 | Z17: 1200000 | AC17: =X17 -> 897744.36 | AD17: =1092668/SUM($AC$17:$AC$22)*AC17 -> 817447.11 | AE17: CE | AF17: Affectation hypothécaire du bien immobilier | AG17: 15.5 | AH17: 50795 | AI17: 0.051 | AJ17: non trouvé | AK17: non trouvé | AM17: 0.0001 | AN17: 0.0001 | AO17: 0.4999 | AP17: 0.4999
A18: GENERAL JULES BRIMONT | B18: 45128 | C18: 78400 | D18: CHATOU | E18: 30 ter avenue de Brimont | G18: Bureau au RDC | K18: oui | M18: Local à usage d'activité | O18: dérogatoire au statut des baux commerciaux | P18: Petits Fils (Pierre Jacques & Co) | Q18: 45717 | R18: 46812 | S18: =905.44*12 -> 10865.28 | T18: non | U18: ILC 3T2024 | V18: =S18 -> 10865.28 | W18: 15.2 | X18: =$L$17/SUM($W$17:$W$22)*W18 -> 52747.253 | Y18: =108673/(SUM($X$17:$X$22))*X18 -> 4776.8352 | AC18: =X18 -> 52747.253 | AD18: =1092668/SUM($AC$17:$AC$22)*AC18 -> 48029.363 | AM18: 0.0001 | AN18: 0.0001 | AO18: 0.4999 | AP18: 0.4999
A19: GENERAL JULES BRIMONT | B19: 45128 | C19: 78400 | D19: CHATOU | E19: 30 ter avenue de Brimont | G19: Local professionnel | K19: oui | M19: Local à usage d'activité | O19: professionnel | P19: Mme BARREIRO(diététicienne) | Q19: 45895 | R19: 48085 | S19: 3185 | T19: non | U19: ICC 4T2024 = 2108 | V19: =S19 -> 3185 | W19: 11.15 | X19: =$L$17/SUM($W$17:$W$22)*W19 -> 38692.886 | Y19: =108673/(SUM($X$17:$X$22))*X19 -> 3504.06 | AC19: =X19 -> 38692.886 | AD19: =1092668/SUM($AC$17:$AC$22)*AC19 -> 35232.065
A20: GENERAL JULES BRIMONT | B20: 45128 | C20: 78400 | D20: CHATOU | E20: 30 ter avenue de Brimont | G20: Local professionnel | K20: oui | M20: Local à usage d'activité | O20: professionnel | P20: Mme JOUBERT (Psychomotricienne) | Q20: 45895 | R20: 48085 | S20: 11788.32 | T20: non | U20: ICC 3T2024 = 2143 | V20: =S20 -> 11788.32 | W20: 16.5 | X20: =$L$17/SUM($W$17:$W$22)*W20 -> 57258.531 | Y20: =108673/(SUM($X$17:$X$22))*X20 -> 5185.3803 | AC20: =X20 -> 57258.531 | AD20: =1092668/SUM($AC$17:$AC$22)*AC20 -> 52137.137 | AM20: 0.0001 | AN20: 0.0001 | AO20: 0.4999 | AP20: 0.4999
A21: GENERAL JULES BRIMONT | B21: 45128 | C21: 78400 | D21: CHATOU | E21: 30 ter avenue de Brimont | G21: Bureau au RDC | H21: Bureau au RDC | J21: Bureau au RDC | K21: Bureau au RDC | M21: Local à usage d'activité | O21: commercial | P21: Mme DENANT (Pédicure) | Q21: 42676 | R21: =Q21+365.25*9 -> 45963.25 | S21: 7084 | T21: non | U21: ILAT | V21: =699.33*12 -> 8391.96 | W21: 33 | X21: =$L$17/SUM($W$17:$W$22)*W21 -> 114517.06 | Y21: =108673/(SUM($X$17:$X$22))*X21 -> 10370.761 | AC21: =X21 -> 114517.06 | AD21: =1092668/SUM($AC$17:$AC$22)*AC21 -> 104274.27 | AM21: 0.0001 | AN21: 0.0001 | AO21: 0.4999 | AP21: 0.4999
A22: GENERAL JULES BRIMONT | B22: 45128 | C22: 78400 | D22: CHATOU | E22: 30 ter avenue de Brimont | G22: Bureau au RDC | H22: Bureau au RDC | J22: Bureau au RDC | K22: Bureau au RDC | M22: Local à usage d'activité | O22: professionnel | P22: Mme DIAZ COURTENAY MAYERS (Pédopsy) | Q22: 45792 | R22: 45791 | S22: 8040.24 | T22: non | U22: ICC 4T2024 = 2108 | V22: =S22 -> 8040.24 | W22: 11.25 | X22: =$L$17/SUM($W$17:$W$22)*W22 -> 39039.907 | Y22: =108673/(SUM($X$17:$X$22))*X22 -> 3535.4866 | AC22: =X22 -> 39039.907 | AD22: =1092668/SUM($AC$17:$AC$22)*AC22 -> 35548.048 | AM22: 0.0001 | AN22: 0.0001 | AO22: 0.4999 | AP22: 0.4999
A23: GENERAL JULES BRIMONT | B23: 45205 | C23: 95130 | D23: PLESSIS BOUCHARD | E23: 56 Chaussée Jules César | G23: Crèche LPB | L23: 740000 | M23: Maison individuelle | O23: commercial | P23: SARL VAL D'OISE | Q23: 45292 | R23: 48944 | S23: 80000 | T23: non | U23: ILC | V23: =20606.02*4 -> 82424.08 | W23: 396.34 | X23: 740000 | Y23: 65750 | Z23: =X23 -> 740000 | AC23: =Z23 -> 740000 | AD23: 686767 | AE23: LCL | AF23: Hypothèque Légale Spéciale de Prêteur de Deniers sur le bien immobilier | AG23: 15 | AH23: 50684 | AI23: 0.46 | AJ23: non trouvé | AK23: 1 semestre d'intérêts au taux conventionnel sur le montant remboursé | AM23: 0.0001 | AN23: 0.0001 | AO23: 0.4999 | AP23: 0.4999
A26: HOCHE ERMONT | B26: VENDU | AM26: 0.0001 | AN26: 0.0001 | AO26: 0.4999 | AP26: 0.4999
A27: MADELI | B27: VENDU | AM27: 0.0001 | AN27: 0.0001 | AO27: 0.4999 | AP27: 0.4999
A28: 22 RUE ARAGO | B28: VENDU | AM28: 0.5 | AN28: 0.5 | AO28: 0 | AP28: 0 | AS28: oui usufruit SAS | AT28: Vendu

Sheet Feuil1
A3: SCI | B3: Banques | C3: Garantie
A4: 34 RUE HAUTE | B4: SG et CE | C4: sur SG caution HIO et AXORIEL sur CE hypothèque et Caution solidaire de la SAS
A10: LEGRAND | B10: BNP | C10: Cautionnement de la SAS + privilège de prêteur de deniers
A11: LEGRAND | B11: SG | C11: Cautionnement de la SAS (546k€)
A12: ARMEE ORIENT | B12: LCL | C12: Affectation hypothécaire du bien immobilier
A13: ARMEE ORIENT | B13: CA | C13: Hypothèque conventionnelle + Cautionnements solidaires HIO et AXORIEL
A14: CHENNEVIERES | B14: LCL | C14: Affectation hypothécaire du bien immobilier
A15: CHENNEVIERES | B15: SG | C15: IPPD et hypothèque.
A16: TAVERNY | B16: CE | C16: Affectation hypothécaire du bien immobilier
A17: GENERAL JULES BRIMONT | B17: CE | C17: Affectation hypothécaire du bien immobilier
A23: GENERAL JULES BRIMONT | B23: LCL | C23: Hypothèque Légale Spéciale de Prêteur de Deniers sur le bien immobilier

Sheet SCI 34 RUE HAUTE
A1: SCI 34 RUE HAUTE
C4: nb m² | D4: LOCATIONS | E4: 2023 | F4: 2024 | G4: 2025 | H4: 2026
D5: =BDD!D4&" "&BDD!G4 -> DEUIL LA BARRE Crèche | H5: =BDD!S4 -> 87000
D6: =BDD!D5&" "&BDD!G5 -> DEUIL LA BARRE Ecole | H6: =BDD!S5 -> 30600
D7: =BDD!D6&" "&BDD!G6 -> DEUIL LA BARRE Logements 1 appartement avec terrasse et jardin RDC | H7: =BDD!S6 -> 10740
D8: =BDD!D7&" "&BDD!G7 -> DEUIL LA BARRE Logements 2 appartement RDC | H8: =BDD!S7 -> 7080
D9: =BDD!D8&" "&BDD!G8 -> DEUIL LA BARRE Logements 3 1er étage à droite | H9: =BDD!S8 -> 10440
D10: =BDD!D9&" "&BDD!G9 -> DEUIL LA BARRE Logements 4 1er étage à gauche | H10: =BDD!S9 -> 12780
D11: Location 7
D12: Location 8
D13: Location 9
D14: Location 10
D16: CHARGES LOCATIVES | E16: 2023 | F16: 2024 | G16: 2025 | H16: 2026
D17: =D5 -> DEUIL LA BARRE Crèche
D18: =D6 -> DEUIL LA BARRE Ecole
D19: =D7 -> DEUIL LA BARRE Logements 1 appartement avec terrasse et jardin RDC
D20: =D8 -> DEUIL LA BARRE Logements 2 appartement RDC
D21: =D9 -> DEUIL LA BARRE Logements 3 1er étage à droite
D22: =D10 -> DEUIL LA BARRE Logements 4 1er étage à gauche
D23: =D11 -> Location 7
D24: =D12 -> Location 8
D25: =D13 -> Location 9
D26: =D14 -> Location 10
E29: 2023 | F29: 2024 | G29: 2025 | H29: 2026
D31: PRODUCTION VENDUE DE SERVICES (Chiffre d'affaires) | E31: =SUM(E32:E35) -> 105549 | F31: =SUM(F32:F35) -> 174596 | G31: =SUM(G32:G35) -> 202520 | H31: =SUM(H32:H35) -> 206570.4 | J31: =G31/0.07 -> 2893142.9
D32: 70650000 LOYERS CRECHES | E32: 91673 | F32: 97146 | G32: 100089 | H32: =G32*(1+I32) -> 102090.78 | I32: 0.02 | J32: =G32/0.07 -> 1429842.9
D33: 70651000 LOYERS LOGEMENTS + ASSOC. | E33: 3698 | F33: 63428 | G33: =176716-G32 -> 76627 | H33: =G33*(1+I33) -> 78159.54 | I33: 0.02 | J33: =G33/0.07 -> 1094671.4
D34: 70880000 REFACT. CH. - CRECHES | E34: 9805 | F34: 7523 | G34: 16931 | H34: =G34*(1+I34) -> 17269.62 | I34: 0.02 | J34: =G34/0.07 -> 241871.43
D35: 70881000 REFACT. CH- LOGEMENTS + ASSO | E35: 373 | F35: 6499 | G35: =25804-G34 -> 8873 | H35: =G35*(1+I35) -> 9050.46 | I35: 0.02 | J35: =G35/0.07 -> 126757.14
D36: AUTRES PRODUITS | E36: =E37 -> 0 | F36: =F37 -> 0 | G36: =G37 -> 4081 | H36: =H37 -> 0 | J36: =G36/0.07 -> 58300
D37: 75800000 PRODUITS DE GESTION COURANTE | E37: 0 | F37: 0 | G37: 4081 | J37: =G37/0.07 -> 58300
D38: Total des Produits d'exploitation | E38: =E37+E31 -> 105549 | F38: =F37+F31 -> 174596 | G38: =G37+G31 -> 206601 | H38: =H37+H31 -> 206570.4 | J38: =G38/0.07 -> 2951442.9
D39: AUTRES ACHATS ET CHARGES EXTERNES | E39: =SUM(E40:E54) -> 36340 | F39: =SUM(F40:F54) -> 27181 | G39: =SUM(G40:G54) -> 32240.37 | H39: =SUM(H40:H54) -> 32887.166
D40: 60611000 EDF | E40: 1976 | F40: 3206 | G40: 1860.2 | H40: =AVERAGE(E40:G40)*(1+I40) -> 2394.348 | I40: 0.02
D41: 60612000 EAU | E41: 2562 | F41: 3339 | G41: 3387 | H41: =AVERAGE(E41:G41)*(1+I41) -> 3157.92 | I41: 0.02
D42: 60613000 GAZ | E42: 894 | F42: 328 | H42: =AVERAGE(E42:G42)*(1+I42) -> 623.22 | I42: 0.02
D43: 60630000 PETITS OUTILLAGES | E43: 1510 | F43: 0 | H43: =AVERAGE(E43:G43)*(1+I43) -> 770.1 | I43: 0.02
D44: 61420000 CHARGES LOCATIVES - LOG.+ ASSO | E44: 270 | F44: 2399 | G44: 3046 | H44: =G44*(1+I44) -> 3106.92 | I44: 0.02
D45: 61510000 ENTRETIEN ET REPARATION CRECHE | F45: 816 | H45: =AVERAGE(E45:G45)*(1+I45) -> 832.32 | I45: 0.02
D46: 61520000 ENTRETIEN ET REPARATION LOG+AS | F46: 120 | H46: =AVERAGE(E46:G46)*(1+I46) -> 122.4 | I46: 0.02
...

Sheet SCI LEGRAND
A1: SCI LEGRAND
C4: nb m² | D4: LOCATIONS | E4: 2023 | F4: 2024 | G4: 2025 | H4: 2026
D5: =BDD!G10 -> Crèche Noisy | H5: =BDD!S10 -> 31284
D6: =BDD!G11 -> Crèche Sceaux | H6: =BDD!S11 -> 62000
D7: Location 3
D8: Location 4
D9: Location 5
D10: Location 6
D11: Location 7
D12: Location 8
D13: Location 9
D14: Location 10
D16: CHARGES LOCATIVES | E16: 2023 | F16: 2024 | G16: 2025 | H16: 2026
D17: =D5 -> Crèche Noisy
D18: =D6 -> Crèche Sceaux
D19: =D7 -> Location 3
D20: =D8 -> Location 4
D21: =D9 -> Location 5
D22: =D10 -> Location 6
D23: =D11 -> Location 7
D24: =D12 -> Location 8
D25: =D13 -> Location 9
D26: =D14 -> Location 10
E29: 2023 | F29: 2024 | G29: 2025 | H29: 2026
D31: PRODUCTION VENDUE DE SERVICES (Chiffre d'affaires) | E31: =SUM(E32:E35) -> 143563 | F31: =SUM(F32:F35) -> 172786 | G31: =SUM(G32:G35) -> 156065 | H31: =SUM(H32:H35) -> 159186.3
D32: 70650000 LOYERS CRECHES | E32: =34794+66410 -> 101204 | F32: =36907+68733 -> 105640 | G32: 108938 | H32: =G32*(1+I32) -> 111116.76 | I32: 0.02
D33: 70651000 LOYERS LOGEMENTS + ASSOC. | H33: =G33*(1+I33) -> 0 | I33: 0.02
D34: 70880000 REFACT. CH. - CRECHES | E34: =19253+23106 -> 42359 | F34: =28552+38594 -> 67146 | G34: 47127 | H34: =G34*(1+I34) -> 48069.54 | I34: 0.02
D35: 70881000 REFACT. CH- LOGEMENTS + ASSO | H35: =G35*(1+I35) -> 0 | I35: 0.02
D36: AUTRES PRODUITS | E36: =E37 -> 0 | F36: =F37 -> 174 | G36: =G37 -> 0 | H36: =H37 -> 0
D37: 75800000 PRODUITS DE GESTION COURANTE | E37: 0 | F37: 174 | G37: 0
D38: Total des Produits d'exploitation | E38: =E37+E31 -> 143563 | F38: =F37+F31 -> 172960 | G38: =G37+G31 -> 156065 | H38: =H37+H31 -> 159186.3
D39: AUTRES ACHATS ET CHARGES EXTERNES | E39: =SUM(E40:E54) -> 45453 | F39: =SUM(F40:F54) -> 41674 | G39: =SUM(G40:G54) -> 44201.7 | H39: =SUM(H40:H54) -> 44839.778
D40: 60611000 EDF | I40: 0.02
D41: 60612000 EAU | I41: 0.02
D42: 60613000 GAZ | I42: 0.02
D43: 60630000 PETITS OUTILLAGES | I43: 0.02
D44: 61420000 CHARGES LOCATIVES - LOG.+ ASSO | E44: =15587+19891 -> 35478 | F44: =11387+22813 -> 34200 | G44: 36665 | H44: =G44*(1+I44) -> 37398.3 | I44: 0.02
D45: 61510000 ENTRETIEN ET REPARATION CRECHE | E45: =2630+3877 -> 6507 | F45: =3159-1159 -> 2000 | G45: 4602.7 | H45: =AVERAGE(E45:G45)*(1+I45) -> 4457.298 | I45: 0.02
D46: 61520000 ENTRETIEN ET REPARATION LOG+AS | I46: 0.02
...

Sheet SCI ARMEE ORIENT
A1: SCI ARMEE ORIENT
C4: nb m² | D4: LOCATIONS | E4: 2023 | F4: 2024 | G4: 2025 | H4: 2026
D5: =BDD!G12 -> Crèche Epone | H5: =BDD!S12 -> 59090
D6: =BDD!G13 -> Crèche Nice | H6: =BDD!S13 -> 55000
D7: Location 3
D8: Location 4
D9: Location 5
D10: Location 6
D11: Location 7
D12: Location 8
D13: Location 9
D14: Location 10
D16: CHARGES LOCATIVES | E16: 2023 | F16: 2024 | G16: 2025 | H16: 2026
D17: =D5 -> Crèche Epone
D18: =D6 -> Crèche Nice
D19: =D7 -> Location 3
D20: =D8 -> Location 4
D21: =D9 -> Location 5
D22: =D10 -> Location 6
D23: =D11 -> Location 7
D24: =D12 -> Location 8
D25: =D13 -> Location 9
D26: =D14 -> Location 10
G28: ok bilan
E29: 2023 | F29: 2024 | G29: 2025 | H29: 2026
D31: PRODUCTION VENDUE DE SERVICES (Chiffre d'affaires) | E31: =SUM(E32:E35) -> 130281 | F31: =SUM(F32:F35) -> 127589 | G31: =SUM(G32:G35) -> 134224 | H31: =SUM(H32:H35) -> 136908.48
D32: 70650000 LOYERS CRECHES | E32: =72500+45833 -> 118333 | F32: =59090+58284 -> 117374 | G32: =60880+60050 -> 120930 | H32: =G32*(1+I32) -> 123348.6 | I32: 0.02 | J32: =G32/0.07 -> 1727571.4
D33: 70651000 LOYERS LOGEMENTS + ASSOC. | H33: =G33*(1+I33) -> 0 | I33: 0.02
D34: 70880000 REFACT. CH. - CRECHES | E34: =7250+4698 -> 11948 | F34: =7189+3026 -> 10215 | G34: =7901+5393 -> 13294 | H34: =G34*(1+I34) -> 13559.88 | I34: 0.02
D35: 70881000 REFACT. CH- LOGEMENTS + ASSO | H35: =G35*(1+I35) -> 0 | I35: 0.02
D36: AUTRES PRODUITS | E36: =E37 -> 0 | F36: =F37 -> 0 | G36: =G37 -> 0 | H36: =H37 -> 0
D37: 75800000 PRODUITS DE GESTION COURANTE | E37: 0 | G37: 0
D38: Total des Produits d'exploitation | E38: =E37+E31 -> 130281 | F38: =F37+F31 -> 127589 | G38: =G37+G31 -> 134224 | H38: =H37+H31 -> 136908.48
D39: AUTRES ACHATS ET CHARGES EXTERNES | E39: =SUM(E40:E54) -> 16996 | F39: =SUM(F40:F54) -> 12398 | G39: =SUM(G40:G54) -> 11693 | H39: =SUM(H40:H54) -> 12024.78
D40: 60611000 EDF | I40: 0.02
D41: 60612000 EAU | I41: 0.02
D42: 60613000 GAZ | I42: 0.02
D43: 60630000 PETITS OUTILLAGES | I43: 0.02
D44: 61420000 CHARGES LOCATIVES - LOG.+ ASSO | E44: =4055+2176 -> 6231 | F44: =2823+3123 -> 5946 | G44: =3191+3075+1 -> 6267 | H44: =G44*(1+I44) -> 6392.34 | I44: 0.02
D45: 61510000 ENTRETIEN ET REPARATION CRECHE | F45: 36 | H45: =AVERAGE(E45:G45)*(1+I45) -> 36.72 | I45: 0.02
...

Sheet SCI CHENNEVIERES
A1: SCI CHENNEVIERES
C4: nb m² | D4: LOCATIONS | E4: 2023 | F4: 2024 | G4: 2025 | H4: 2026
D5: =BDD!G14 -> Crèche Chennevières | H5: =BDD!S14 -> 75240
D6: =BDD!G15 -> Crèche Alforville | H6: =BDD!S15 -> 86100
D7: Location 3
D8: Location 4
D9: Location 5
D10: Location 6
D11: Location 7
D12: Location 8
D13: Location 9
D14: Location 10
D16: CHARGES LOCATIVES | E16: 2023 | F16: 2024 | G16: 2025 | H16: 2026
D17: =D5 -> Crèche Chennevières
D18: =D6 -> Crèche Alforville
D19: =D7 -> Location 3
D20: =D8 -> Location 4
D21: =D9 -> Location 5
D22: =D10 -> Location 6
D23: =D11 -> Location 7
D24: =D12 -> Location 8
D25: =D13 -> Location 9
D26: =D14 -> Location 10
G28: ok bilan
E29: 2023 | F29: 2024 | G29: 2025 | H29: 2026
D31: PRODUCTION VENDUE DE SERVICES (Chiffre d'affaires) | E31: =SUM(E32:E35) -> 0 | F31: =SUM(F32:F35) -> 103516 | G31: =SUM(G32:G35) -> 185609 | H31: =SUM(H32:H35) -> 189321.18
D32: 70650000 LOYERS CRECHES | F32: =57580+28544 -> 86124 | G32: =78940+88709 -> 167649 | H32: =G32*(1+I32) -> 171001.98 | I32: 0.02
D33: 70651000 LOYERS LOGEMENTS + ASSOC. | H33: =G33*(1+I33) -> 0 | I33: 0.02
D34: 70880000 REFACT. CH. - CRECHES | F34: =13232+4160 -> 17392 | G34: =4891+13069 -> 17960 | H34: =G34*(1+I34) -> 18319.2 | I34: 0.02
D35: 70881000 REFACT. CH- LOGEMENTS + ASSO | H35: =G35*(1+I35) -> 0 | I35: 0.02
D36: AUTRES PRODUITS | E36: =E37 -> 0 | F36: =F37 -> 0 | G36: =G37 -> 0 | H36: =H37 -> 0
D37: 75800000 PRODUITS DE GESTION COURANTE | E37: 0 | G37: 0
D38: Total des Produits d'exploitation | E38: =E37+E31 -> 0 | F38: =F37+F31 -> 103516 | G38: =G37+G31 -> 185609 | H38: =H37+H31 -> 189321.18
D39: AUTRES ACHATS ET CHARGES EXTERNES | E39: =SUM(E40:E54) -> 108780 | F39: =SUM(F40:F54) -> 29714 | G39: =SUM(G40:G54) -> 14565 | H39: =SUM(H40:H54) -> 14683.92
D40: 60611000 EDF | I40: 0.02
D41: 60612000 EAU | I41: 0.02
D42: 60613000 GAZ | I42: 0.02
D43: 60630000 PETITS OUTILLAGES | I43: 0.02
D44: 61420000 CHARGES LOCATIVES - LOG.+ ASSO | E44: 2226 | F44: =12560+5822 -> 18382 | G44: =1263+7096 -> 8359 | H44: =G44*(1+I44) -> 8526.18 | I44: 0.02
D45: 61510000 ENTRETIEN ET REPARATION CRECHE | G45: 215 | H45: =G45*(1+I45) -> 219.3 | I45: 0.02
...

Sheet SCI TAVERNY
A1: SCI TAVERNY
C4: nb m² | D4: LOCATIONS | E4: 2023 | F4: 2024 | G4: 2025 | H4: 2026
D5: =BDD!G16 -> Crèche Taverny | H5: =BDD!S16 -> 67000
D6: Location 2
D7: Location 3
D8: Location 4
D9: Location 5
D10: Location 6
D11: Location 7
D12: Location 8
D13: Location 9
D14: Location 10
D16: CHARGES LOCATIVES | E16: 2023 | F16: 2024 | G16: 2025 | H16: 2026
D17: =D5 -> Crèche Taverny
D18: =D6 -> Location 2
D19: =D7 -> Location 3
D20: =D8 -> Location 4
D21: =D9 -> Location 5
D22: =D10 -> Location 6
D23: =D11 -> Location 7
D24: =D12 -> Location 8
D25: =D13 -> Location 9
D26: =D14 -> Location 10
E29: 2023 | F29: 2024 | G29: 2025 | H29: 2026
D31: PRODUCTION VENDUE DE SERVICES (Chiffre d'affaires) | E31: =SUM(E32:E35) -> 0 | F31: =SUM(F32:F35) -> 0 | G31: =SUM(G32:G35) -> 0 | H31: =SUM(H32:H35) -> 67000
D32: 70650000 LOYERS CRECHES | H32: =H5 -> 67000 | I32: 0.02
D33: 70651000 LOYERS LOGEMENTS + ASSOC. | H33: =G33*(1+I33) -> 0 | I33: 0.02
D34: 70880000 REFACT. CH. - CRECHES | H34: =G34*(1+I34) -> 0 | I34: 0.02
D35: 70881000 REFACT. CH- LOGEMENTS + ASSO | H35: =G35*(1+I35) -> 0 | I35: 0.02
D36: AUTRES PRODUITS | E36: =E37 -> 0 | F36: =F37 -> 0 | G36: =G37 -> 0 | H36: =H37 -> 0
D37: 75800000 PRODUITS DE GESTION COURANTE | E37: 0 | G37: 0
D38: Total des Produits d'exploitation | E38: =E37+E31 -> 0 | F38: =F37+F31 -> 0 | G38: =G37+G31 -> 0 | H38: =H37+H31 -> 67000
D39: AUTRES ACHATS ET CHARGES EXTERNES | E39: =SUM(E40:E54) -> 20051 | F39: =SUM(F40:F54) -> 117742 | G39: =SUM(G40:G54) -> 11296 | H39: =SUM(H40:H54) -> 11521.92
D40: 60611000 EDF | I40: 0.02
D41: 60612000 EAU | I41: 0.02
D42: 60613000 GAZ | I42: 0.02
D43: 60630000 PETITS OUTILLAGES | I43: 0.02
D44: 61420000 CHARGES LOCATIVES - LOG.+ ASSO | H44: =G44*(1+I44) -> 0 | I44: 0.02
D45: 61510000 ENTRETIEN ET REPARATION CRECHE | I45: 0.02
D46: 61520000 ENTRETIEN ET REPARATION LOG+AS | I46: 0.02
...

Sheet SCI GENERAL JULES BRIMONT
A1: SCI GENERAL JULES BRIMONT
C4: nb m² | D4: LOCATIONS | E4: 2023 | F4: 2024 | G4: 2025 | H4: 2026
D5: =BDD!G17 -> Crèche Chatou | H5: =BDD!S17 -> 84000
D6: =BDD!G18 -> Bureau au RDC | H6: =BDD!S18 -> 10865.28
D7: =BDD!G19 -> Local professionnel | H7: =BDD!S19 -> 3185
D8: =BDD!G20 -> Local professionnel | H8: =BDD!S20 -> 11788.32
D9: =BDD!G21 -> Bureau au RDC | H9: =BDD!S21 -> 7084
D10: =BDD!G22 -> Bureau au RDC | H10: =BDD!S22 -> 8040.24
D11: =BDD!G23 -> Crèche LPB | H11: =BDD!S23 -> 80000
D12: Location 8
D13: Location 9
D14: Location 10
D16: CHARGES LOCATIVES | E16: 2023 | F16: 2024 | G16: 2025 | H16: 2026
D17: =D5 -> Crèche Chatou
D18: =D6 -> Bureau au RDC
D19: =D7 -> Local professionnel
D20: =D8 -> Local professionnel
D21: =D9 -> Bureau au RDC
D22: =D10 -> Bureau au RDC
D23: =D11 -> Crèche LPB
D24: =D12 -> Location 8
D25: =D13 -> Location 9
D26: =D14 -> Location 10
E29: 2023 | F29: 2024 | G29: 2025 | H29: 2026
D31: PRODUCTION VENDUE DE SERVICES (Chiffre d'affaires) | E31: =SUM(E32:E35) -> 4984 | F31: =SUM(F32:F35) -> 73888 | G31: =SUM(G32:G35) -> 229252 | H31: =SUM(H32:H35) -> 244653.98
D32: 70650000 LOYERS CRECHES | F32: =29127+26522 -> 55649 | G32: 170486 | H32: =G32*(1+I32) -> 173895.72 | I32: 0.02
D33: 70651000 LOYERS LOGEMENTS + ASSOC. | E33: 3534 | F33: 8049 | G33: =200844-G32 -> 30358 | H33: =SUM(H6:H10)*(1+I33) -> 41782.097 | I33: 0.02
D34: 70880000 REFACT. CH. - CRECHES | F34: =5752+2828 -> 8580 | G34: 24467 | H34: =G34*(1+I34) -> 24956.34 | I34: 0.02
D35: 70881000 REFACT. CH- LOGEMENTS + ASSO | E35: 1450 | F35: 1610 | G35: =28408-G34 -> 3941 | H35: =G35*(1+I35) -> 4019.82 | I35: 0.02
D36: AUTRES PRODUITS | E36: =E37 -> 0 | F36: =F37 -> 0 | G36: =G37 -> 0 | H36: =H37 -> 0
D37: 75800000 PRODUITS DE GESTION COURANTE | E37: 0 | G37: 0
D38: Total des Produits d'exploitation | E38: =E37+E31 -> 4984 | F38: =F37+F31 -> 73888 | G38: =G37+G31 -> 229252 | H38: =H37+H31 -> 244653.98
D39: AUTRES ACHATS ET CHARGES EXTERNES | E39: =SUM(E40:E54) -> 189144 | F39: =SUM(F40:F54) -> 34964 | G39: =SUM(G40:G54) -> 36411 | H39: =SUM(H40:H54) -> 37057.62
D40: 60611000 EDF | I40: 0.02
D41: 60612000 EAU | I41: 0.02
D42: 60613000 GAZ | I42: 0.02
D43: 60630000 PETITS OUTILLAGES | G43: 80 | I43: 0.02
D44: 61420000 CHARGES LOCATIVES - LOG.+ ASSO | E44: 5113 | F44: 8277 | G44: 9497 | H44: =G44*(1+I44) -> 9686.94 | I44: 0.02
D45: 61510000 ENTRETIEN ET REPARATION CRECHE | E45: 1602 | F45: =5942+3380 -> 9322 | G45: 8050 | H45: =G45*(1+I45) -> 8211 | I45: 0.02
D46: 61520000 ENTRETIEN ET REPARATION LOG+AS | I46: 0.02
...

Sheet CONSO
A1: SCI 34 RUE HAUTE
C4: nb m² | D4: LOCATIONS | E4: 2023 | F4: 2024 | G4: 2025 | H4: 2026
D5: =BDD!D4&" "&BDD!G4 -> DEUIL LA BARRE Crèche
D6: =BDD!D5&" "&BDD!G5 -> DEUIL LA BARRE Ecole
D7: =BDD!D6&" "&BDD!G6 -> DEUIL LA BARRE Logements 1 appartement avec terrasse et jardin RDC
D8: =BDD!D7&" "&BDD!G7 -> DEUIL LA BARRE Logements 2 appartement RDC
D9: =BDD!D8&" "&BDD!G8 -> DEUIL LA BARRE Logements 3 1er étage à droite
D10: =BDD!D9&" "&BDD!G9 -> DEUIL LA BARRE Logements 4 1er étage à gauche
D11: Location 7
D12: Location 8
D13: Location 9
D14: Location 10
D16: CHARGES LOCATIVES | E16: 2023 | F16: 2024 | G16: 2025 | H16: 2026
D17: =D5 -> DEUIL LA BARRE Crèche
D18: =D6 -> DEUIL LA BARRE Ecole
D19: =D7 -> DEUIL LA BARRE Logements 1 appartement avec terrasse et jardin RDC
D20: =D8 -> DEUIL LA BARRE Logements 2 appartement RDC
D21: =D9 -> DEUIL LA BARRE Logements 3 1er étage à droite
D22: =D10 -> DEUIL LA BARRE Logements 4 1er étage à gauche
D23: =D11 -> Location 7
D24: =D12 -> Location 8
D25: =D13 -> Location 9
D26: =D14 -> Location 10
E29: 2023 | F29: 2024 | G29: 2025 | H29: 2026
D31: PRODUCTION VENDUE DE SERVICES (Chiffre d'affaires) | E31: =SUM(E32:E35) -> 384377 | F31: =SUM(F32:F35) -> 652375 | G31: =SUM(G32:G35) -> 907670 | H31: =SUM(H32:H35) -> 1003640.3
D32: 70650000 LOYERS CRECHES | E32: ='SCI 34 RUE HAUTE'!E32+'SCI LEGRAND'!E32+'SCI ARMEE ORIENT'!E32+'SCI CHENNEVIERES'!E32+'SCI TAVERNY'!E32+'SCI GENERAL JULES BRIMONT'!E32 -> 311210 | F32: ='SCI 34 RUE HAUTE'!F32+'SCI LEGRAND'!F32+'SCI ARMEE ORIENT'!F32+'SCI CHENNEVIERES'!F32+'SCI TAVERNY'!F32+'SCI GENERAL JULES BRIMONT'!F32 -> 461933 | G32: ='SCI 34 RUE HAUTE'!G32+'SCI LEGRAND'!G32+'SCI ARMEE ORIENT'!G32+'SCI CHENNEVIERES'!G32+'SCI TAVERNY'!G32+'SCI GENERAL JULES BRIMONT'!G32 -> 668092 | H32: ='SCI 34 RUE HAUTE'!H32+'SCI LEGRAND'!H32+'SCI ARMEE ORIENT'!H32+'SCI CHENNEVIERES'!H32+'SCI TAVERNY'!H32+'SCI GENERAL JULES BRIMONT'!H32 -> 748453.84
D33: 70651000 LOYERS LOGEMENTS + ASSOC. | E33: ='SCI 34 RUE HAUTE'!E33+'SCI LEGRAND'!E33+'SCI ARMEE ORIENT'!E33+'SCI CHENNEVIERES'!E33+'SCI TAVERNY'!E33+'SCI GENERAL JULES BRIMONT'!E33 -> 7232 | F33: ='SCI 34 RUE HAUTE'!F33+'SCI LEGRAND'!F33+'SCI ARMEE ORIENT'!F33+'SCI CHENNEVIERES'!F33+'SCI TAVERNY'!F33+'SCI GENERAL JULES BRIMONT'!F33 -> 71477 | G33: ='SCI 34 RUE HAUTE'!G33+'SCI LEGRAND'!G33+'SCI ARMEE ORIENT'!G33+'SCI CHENNEVIERES'!G33+'SCI TAVERNY'!G33+'SCI GENERAL JULES BRIMONT'!G33 -> 106985 | H33: ='SCI 34 RUE HAUTE'!H33+'SCI LEGRAND'!H33+'SCI ARMEE ORIENT'!H33+'SCI CHENNEVIERES'!H33+'SCI TAVERNY'!H33+'SCI GENERAL JULES BRIMONT'!H33 -> 119941.64
D34: 70880000 REFACT. CH. - CRECHES | E34: ='SCI 34 RUE HAUTE'!E34+'SCI LEGRAND'!E34+'SCI ARMEE ORIENT'!E34+'SCI CHENNEVIERES'!E34+'SCI TAVERNY'!E34+'SCI GENERAL JULES BRIMONT'!E34 -> 64112 | F34: ='SCI 34 RUE HAUTE'!F34+'SCI LEGRAND'!F34+'SCI ARMEE ORIENT'!F34+'SCI CHENNEVIERES'!F34+'SCI TAVERNY'!F34+'SCI GENERAL JULES BRIMONT'!F34 -> 110856 | G34: ='SCI 34 RUE HAUTE'!G34+'SCI LEGRAND'!G34+'SCI ARMEE ORIENT'!G34+'SCI CHENNEVIERES'!G34+'SCI TAVERNY'!G34+'SCI GENERAL JULES BRIMONT'!G34 -> 119779 | H34: ='SCI 34 RUE HAUTE'!H34+'SCI LEGRAND'!H34+'SCI ARMEE ORIENT'!H34+'SCI CHENNEVIERES'!H34+'SCI TAVERNY'!H34+'SCI GENERAL JULES BRIMONT'!H34 -> 122174.58
D35: 70881000 REFACT. CH- LOGEMENTS + ASSO | E35: ='SCI 34 RUE HAUTE'!E35+'SCI LEGRAND'!E35+'SCI ARMEE ORIENT'!E35+'SCI CHENNEVIERES'!E35+'SCI TAVERNY'!E35+'SCI GENERAL JULES BRIMONT'!E35 -> 1823 | F35: ='SCI 34 RUE HAUTE'!F35+'SCI LEGRAND'!F35+'SCI ARMEE ORIENT'!F35+'SCI CHENNEVIERES'!F35+'SCI TAVERNY'!F35+'SCI GENERAL JULES BRIMONT'!F35 -> 8109 | G35: ='SCI 34 RUE HAUTE'!G35+'SCI LEGRAND'!G35+'SCI ARMEE ORIENT'!G35+'SCI CHENNEVIERES'!G35+'SCI TAVERNY'!G35+'SCI GENERAL JULES BRIMONT'!G35 -> 12814 | H35: ='SCI 34 RUE HAUTE'!H35+'SCI LEGRAND'!H35+'SCI ARMEE ORIENT'!H35+'SCI CHENNEVIERES'!H35+'SCI TAVERNY'!H35+'SCI GENERAL JULES BRIMONT'!H35 -> 13070.28
D36: AUTRES PRODUITS | E36: =E37 -> 0 | F36: =F37 -> 174 | G36: =G37 -> 4081 | H36: =H37 -> 0
D37: 75800000 PRODUITS DE GESTION COURANTE | E37: ='SCI 34 RUE HAUTE'!E37+'SCI LEGRAND'!E37+'SCI ARMEE ORIENT'!E37+'SCI CHENNEVIERES'!E37+'SCI TAVERNY'!E37+'SCI GENERAL JULES BRIMONT'!E37 -> 0 | F37: ='SCI 34 RUE HAUTE'!F37+'SCI LEGRAND'!F37+'SCI ARMEE ORIENT'!F37+'SCI CHENNEVIERES'!F37+'SCI TAVERNY'!F37+'SCI GENERAL JULES BRIMONT'!F37 -> 174 | G37: ='SCI 34 RUE HAUTE'!G37+'SCI LEGRAND'!G37+'SCI ARMEE ORIENT'!G37+'SCI CHENNEVIERES'!G37+'SCI TAVERNY'!G37+'SCI GENERAL JULES BRIMONT'!G37 -> 4081 | H37: ='SCI 34 RUE HAUTE'!H37+'SCI LEGRAND'!H37+'SCI ARMEE ORIENT'!H37+'SCI CHENNEVIERES'!H37+'SCI TAVERNY'!H37+'SCI GENERAL JULES BRIMONT'!H37 -> 0
D38: Total des Produits d'exploitation | E38: =E37+E31 -> 384377 | F38: =F37+F31 -> 652549 | G38: =G37+G31 -> 911751 | H38: =H37+H31 -> 1003640.3
D39: AUTRES ACHATS ET CHARGES EXTERNES | E39: =SUM(E40:E54) -> 416764 | F39: =SUM(F40:F54) -> 263673 | G39: =SUM(G40:G54) -> 150407.07 | H39: =SUM(H40:H54) -> 153015.18
D40: 60611000 EDF | E40: ='SCI 34 RUE HAUTE'!E40+'SCI LEGRAND'!E40+'SCI ARMEE ORIENT'!E40+'SCI CHENNEVIERES'!E40+'SCI TAVERNY'!E40+'SCI GENERAL JULES BRIMONT'!E40 -> 1976 | F40: ='SCI 34 RUE HAUTE'!F40+'SCI LEGRAND'!F40+'SCI ARMEE ORIENT'!F40+'SCI CHENNEVIERES'!F40+'SCI TAVERNY'!F40+'SCI GENERAL JULES BRIMONT'!F40 -> 3206 | G40: ='SCI 34 RUE HAUTE'!G40+'SCI LEGRAND'!G40+'SCI ARMEE ORIENT'!G40+'SCI CHENNEVIERES'!G40+'SCI TAVERNY'!G40+'SCI GENERAL JULES BRIMONT'!G40 -> 1860.2 | H40: ='SCI 34 RUE HAUTE'!H40+'SCI LEGRAND'!H40+'SCI ARMEE ORIENT'!H40+'SCI CHENNEVIERES'!H40+'SCI TAVERNY'!H40+'SCI GENERAL JULES BRIMONT'!H40 -> 2394.348
D41: 60612000 EAU | E41: ='SCI 34 RUE HAUTE'!E41+'SCI LEGRAND'!E41+'SCI ARMEE ORIENT'!E41+'SCI CHENNEVIERES'!E41+'SCI TAVERNY'!E41+'SCI GENERAL JULES BRIMONT'!E41 -> 2562 | F41: ='SCI 34 RUE HAUTE'!F41+'SCI LEGRAND'!F41+'SCI ARMEE ORIENT'!F41+'SCI CHENNEVIERES'!F41+'SCI TAVERNY'!F41+'SCI GENERAL JULES BRIMONT'!F41 -> 3339 | G41: ='SCI 34 RUE HAUTE'!G41+'SCI LEGRAND'!G41+'SCI ARMEE ORIENT'!G41+'SCI CHENNEVIERES'!G41+'SCI TAVERNY'!G41+'SCI GENERAL JULES BRIMONT'!G41 -> 3387 | H41: ='SCI 34 RUE HAUTE'!H41+'SCI LEGRAND'!H41+'SCI ARMEE ORIENT'!H41+'SCI CHENNEVIERES'!H41+'SCI TAVERNY'!H41+'SCI GENERAL JULES BRIMONT'!H41 -> 3157.92
D42: 60613000 GAZ | E42: ='SCI 34 RUE HAUTE'!E42+'SCI LEGRAND'!E42+'SCI ARMEE ORIENT'!E42+'SCI CHENNEVIERES'!E42+'SCI TAVERNY'!E42+'SCI GENERAL JULES BRIMONT'!E42 -> 894 | F42: ='SCI 34 RUE HAUTE'!F42+'SCI LEGRAND'!F42+'SCI ARMEE ORIENT'!F42+'SCI CHENNEVIERES'!F42+'SCI TAVERNY'!F42+'SCI GENERAL JULES BRIMONT'!F42 -> 328 | G42: ='SCI 34 RUE HAUTE'!G42+'SCI LEGRAND'!G42+'SCI ARMEE ORIENT'!G42+'SCI CHENNEVIERES'!G42+'SCI TAVERNY'!G42+'SCI GENERAL JULES BRIMONT'!G42 -> 0 | H42: ='SCI 34 RUE HAUTE'!H42+'SCI LEGRAND'!H42+'SCI ARMEE ORIENT'!H42+'SCI CHENNEVIERES'!H42+'SCI TAVERNY'!H42+'SCI GENERAL JULES BRIMONT'!H42 -> 623.22
D43: 60630000 PETITS OUTILLAGES | E43: ='SCI 34 RUE HAUTE'!E43+'SCI LEGRAND'!E43+'SCI ARMEE ORIENT'!E43+'SCI CHENNEVIERES'!E43+'SCI TAVERNY'!E43+'SCI GENERAL JULES BRIMONT'!E43 -> 1510 | F43: ='SCI 34 RUE HAUTE'!F43+'SCI LEGRAND'!F43+'SCI ARMEE ORIENT'!F43+'SCI CHENNEVIERES'!F43+'SCI TAVERNY'!F43+'SCI GENERAL JULES BRIMONT'!F43 -> 0 | G43: ='SCI 34 RUE HAUTE'!G43+'SCI LEGRAND'!G43+'SCI ARMEE ORIENT'!G43+'SCI CHENNEVIERES'!G43+'SCI TAVERNY'!G43+'SCI GENERAL JULES BRIMONT'!G43 -> 80 | H43: ='SCI 34 RUE HAUTE'!H43+'SCI LEGRAND'!H43+'SCI ARMEE ORIENT'!H43+'SCI CHENNEVIERES'!H43+'SCI TAVERNY'!H43+'SCI GENERAL JULES BRIMONT'!H43 -> 770.1
D44: 61420000 CHARGES LOCATIVES - LOG.+ ASSO | E44: ='SCI 34 RUE HAUTE'!E44+'SCI LEGRAND'!E44+'SCI ARMEE ORIENT'!E44+'SCI CHENNEVIERES'!E44+'SCI TAVERNY'!E44+'SCI GENERAL JULES BRIMONT'!E44 -> 49318 | F44: ='SCI 34 RUE HAUTE'!F44+'SCI LEGRAND'!F44+'SCI ARMEE ORIENT'!F44+'SCI CHENNEVIERES'!F44+'SCI TAVERNY'!F44+'SCI GENERAL JULES BRIMONT'!F44 -> 69204 | G44: ='SCI 34 RUE HAUTE'!G44+'SCI LEGRAND'!G44+'SCI ARMEE ORIENT'!G44+'SCI CHENNEVIERES'!G44+'SCI TAVERNY'!G44+'SCI GENERAL JULES BRIMONT'!G44 -> 63834 | H44: ='SCI 34 RUE HAUTE'!H44+'SCI LEGRAND'!H44+'SCI ARMEE ORIENT'!H44+'SCI CHENNEVIERES'!H44+'SCI TAVERNY'!H44+'SCI GENERAL JULES BRIMONT'!H44 -> 65110.68
D45: 61510000 ENTRETIEN ET REPARATION CRECHE | E45: ='SCI 34 RUE HAUTE'!E45+'SCI LEGRAND'!E45+'SCI ARMEE ORIENT'!E45+'SCI CHENNEVIERES'!E45+'SCI TAVERNY'!E45+'SCI GENERAL JULES BRIMONT'!E45 -> 8109 | F45: ='SCI 34 RUE HAUTE'!F45+'SCI LEGRAND'!F45+'SCI ARMEE ORIENT'!F45+'SCI CHENNEVIERES'!F45+'SCI TAVERNY'!F45+'SCI GENERAL JULES BRIMONT'!F45 -> 12174 | G45: ='SCI 34 RUE HAUTE'!G45+'SCI LEGRAND'!G45+'SCI ARMEE ORIENT'!G45+'SCI CHENNEVIERES'!G45+'SCI TAVERNY'!G45+'SCI GENERAL JULES BRIMONT'!G45 -> 12867.7 | H45: ='SCI 34 RUE HAUTE'!H45+'SCI LEGRAND'!H45+'SCI ARMEE ORIENT'!H45+'SCI CHENNEVIERES'!H45+'SCI TAVERNY'!H45+'SCI GENERAL JULES BRIMONT'!H45 -> 13756.638
D46: 61520000 ENTRETIEN ET REPARATION LOG+AS | E46: ='SCI 34 RUE HAUTE'!E46+'SCI LEGRAND'!E46+'SCI ARMEE ORIENT'!E46+'SCI CHENNEVIERES'!E46+'SCI TAVERNY'!E46+'SCI GENERAL JULES BRIMONT'!E46 -> 0 | F46: ='SCI 34 RUE HAUTE'!F46+'SCI LEGRAND'!F46+'SCI ARMEE ORIENT'!F46+'SCI CHENNEVIERES'!F46+'SCI TAVERNY'!F46+'SCI GENERAL JULES BRIMONT'!F46 -> 120 | G46: ='SCI 34 RUE HAUTE'!G46+'SCI LEGRAND'!G46+'SCI ARMEE ORIENT'!G46+'SCI CHENNEVIERES'!G46+'SCI TAVERNY'!G46+'SCI GENERAL JULES BRIMONT'!G46 -> 0 | H46: ='SCI 34 RUE HAUTE'!H46+'SCI LEGRAND'!H46+'SCI ARMEE ORIENT'!H46+'SCI CHENNEVIERES'!H46+'SCI TAVERNY'!H46+'SCI GENERAL JULES BRIMONT'!H46 -> 122.4
...

Sheet Emprunts
Y2: =V7-X7 -> 104903.87
B3: Nom prêt | C3: Société | D3: Banque | F3: N° cpte compta | G3: Montant prêt | I3: Date 1ere échéance | K3: 2020 | M3: 2021 | O3: 2022 | Q3: 2023 | S3: 2024 | U3: 2025 | W3: 2026 | Y3: 2027 | AA3: 2028 | AC3: 2029 | AE3: 2030 | AG3: 2031 | AI3: 2032 | AK3: 2033 | AM3: 2034 | AO3: 2035 | AQ3: 2036 | AS3: 2037 | AU3: 2038 | AW3: 2039 | AY3: 2040 | BA3: 2041 | BC3: 2042 | BE3: 2043
K4: Échéance (K+I) | L4: solde fin K | M4: Échéance | N4: solde fin | O4: Échéance | P4: solde fin | Q4: Échéance | R4: solde fin | S4: Échéance | T4: solde fin | U4: Échéance | V4: ="solde fin"&" "&U3 -> solde fin 2025 | W4: Échéance | X4: ="solde fin"&" "&W3 -> solde fin 2026 | Y4: Échéance | Z4: ="solde fin"&" "&Y3 -> solde fin 2027 | AA4: Échéance | AB4: ="solde fin"&" "&AA3 -> solde fin 2028 | AC4: Échéance | AD4: ="solde fin"&" "&AC3 -> solde fin 2029 | AE4: Échéance | AF4: ="solde fin"&" "&AE3 -> solde fin 2030 | AG4: Échéance | AH4: ="solde fin"&" "&AG3 -> solde fin 2031 | AI4: Échéance | AJ4: ="solde fin"&" "&AI3 -> solde fin 2032 | AK4: Échéance | AL4: ="solde fin"&" "&AK3 -> solde fin 2033 | AM4: Échéance | AN4: ="solde fin"&" "&AM3 -> solde fin 2034 | AO4: Échéance | AP4: ="solde fin"&" "&AO3 -> solde fin 2035 | AQ4: Échéance | AR4: ="solde fin"&" "&AQ3 -> solde fin 2036 | AS4: Échéance | AT4: ="solde fin"&" "&AS3 -> solde fin 2037 | AU4: Échéance | AV4: ="solde fin"&" "&AU3 -> solde fin 2038 | AW4: Échéance | AX4: ="solde fin"&" "&AW3 -> solde fin 2039 | AY4: Échéance | AZ4: ="solde fin"&" "&AY3 -> solde fin 2040 | BA4: Échéance | BB4: ="solde fin"&" "&BA3 -> solde fin 2041 | BC4: Échéance | BD4: ="solde fin"&" "&BC3 -> solde fin 2042 | BE4: Échéance | BF4: ="solde fin"&" "&BE3 -> solde fin 2043
B5: CE_SCI HOCHE | C5: 9-HOCHE | D5: CE | F5: 0 | G5: 435000 | H5: 0.013 | I5: 44140 | K5: 5488.74 | L5: 430451.3 | M5: 32932.44 | N5: 402951.25 | O5: 32932.44 | P5: 375091.57 | Q5: 32932.44 | R5: 346867.55 | S5: 32932.44 | T5: 318274.42 | U5: 319972.38 | V5: 0.0028812288 | W5: 0 | X5: 0 | Y5: 0 | Z5: 0 | AA5: 0 | AB5: 0 | AC5: 0 | AD5: 0 | AE5: 0 | AF5: 0 | AG5: 0 | AH5: 0 | AI5: 0 | AJ5: 0 | AK5: 0 | AL5: 0 | AM5: 0 | AN5: 0 | AO5: 0 | AP5: 0 | AQ5: 0 | AR5: 0 | AS5: 0 | AT5: 0 | AU5: 0 | AV5: 0 | AW5: 0 | AX5: 0 | AY5: 0 | AZ5: 0 | BA5: 0 | BB5: 0 | BC5: 0 | BD5: 0 | BE5: 0 | BF5: 0 | BH5: =(V5-X5)-U5 -> -319972.38
B6: CE_SCI 34 HAUTE | C6: 9-HAUTE | D6: CE | F6: 0 | G6: 409000 | H6: 0.0135 | I6: 44656 | K6: 0 | L6: 0 | M6: 0 | N6: 0 | O6: 24322.14 | P6: 388727.93 | Q6: 32429.52 | R6: 361377.42 | S6: 32429.52 | T6: 333655.38 | U6: 32429.52 | V6: 305556.77 | W6: 32429.52 | X6: 277076.48 | Y6: 32429.52 | Z6: 248209.31 | AA6: 32429.52 | AB6: 218950.01 | AC6: 32429.52 | AD6: 189293.27 | AE6: 32429.52 | AF6: 159234 | AG6: 32429.52 | AH6: 128766 | AI6: 32429.52 | AJ6: 97884 | AK6: 32429.52 | AL6: 66583 | AM6: 32429.52 | AN6: 34856 | AO6: 2698 | AP6: 0 | AQ6: 0 | AR6: 0 | AS6: 0 | AT6: 0 | AU6: 0 | AV6: 0 | AW6: 0 | AX6: 0 | AY6: 0 | AZ6: 0 | BA6: 0 | BB6: 0 | BC6: 0 | BD6: 0 | BE6: 0 | BF6: 0 | BH6: =(V6-X6)-U6 -> -3949.2239
B7: CE_SCI 34 HAUTE | C7: 9-HAUTE | D7: CE | F7: 220154G | G7: 1515000 | H7: 0.0135 | I7: 44814 | K7: 0 | L7: 0 | M7: 0 | N7: 0 | O7: 40041.28 | P7: 1481720.1 | Q7: 120123.84 | R7: 1380977.7 | S7: 120123.84 | T7: 1278866.8 | U7: 120123.84 | V7: 1175368.8 | W7: 120123.84 | X7: 1070464.9 | Y7: 120123.84 | Z7: 964136.04 | AA7: 120123.84 | AB7: 856362.81 | AC7: 120123.84 | AD7: 747125.61 | AE7: 120123.84 | AF7: 636405 | AG7: 120123.84 | AH7: 524179 | AI7: 120123.84 | AJ7: 410430 | AK7: 120123.84 | AL7: 295135 | AM7: 120123.84 | AN7: 178274 | AO7: =AM7 -> 120123.84 | AP7: 59826 | AQ7: 59826 | AR7: 0 | AS7: 0 | AT7: 0 | AU7: 0 | AV7: 0 | AW7: 0 | AX7: 0 | AY7: 0 | AZ7: 0 | BA7: 0 | BB7: 0 | BC7: 0 | BD7: 0 | BE7: 0 | BF7: 0 | BH7: =(V7-X7)-U7 -> -15219.967
B8: SG_SCI 34 HAUTE | C8: 9-HAUTE | D8: SG | F8: 225003100788 | G8: 350000 | H8: 0.0353 | I8: 45701 | K8: 0 | L8: 0 | M8: 0 | N8: 0 | O8: 0 | P8: 0 | Q8: 0 | R8: 0 | S8: 0 | T8: 0 | U8: 51796.03 | V8: 308928.85 | W8: 56504.76 | X8: 262584.23 | Y8: 56504.76 | Z8: 214576.92 | AA8: 56504.76 | AB8: 164847.26 | AC8: 56504.76 | AD8: 113333.46 | AE8: 56504.76 | AF8: 59972 | AG8: 56504.76 | AH8: 4965 | AI8: 4965 | AJ8: 0 | AK8: 0 | AM8: 0 | AO8: 0 | AQ8: 0 | AS8: 0 | AU8: 0 | AW8: 0 | AY8: 0 | BA8: 0 | BC8: 0 | BE8: 0 | BH8: =(V8-X8)-U8 -> -5451.413
B9: BNP_SCI LEGRAND | C9: 9-LEGRAND | D9: BNP | F9: 0 | G9: 239977.57 | H9: 0.01 | I9: 43118 | K9: 16504.968 | L9: 161724.07 | M9: 32775.176 | N9: 130422.67 | O9: 32462.162 | P9: 99121.27 | Q9: 32149.148 | R9: 67819.87 | S9: 31836.134 | T9: 36518.47 | U9: 31523.12 | V9: 5217.07 | W9: 5221.4176 | X9: 0 | Y9: 0 | Z9: 0 | AA9: 0 | AB9: 0 | AC9: 0 | AD9: 0 | AE9: 0 | AG9: 0 | AI9: 0 | AK9: 0 | AM9: 0 | AO9: 0 | AQ9: 0 | AS9: 0 | AU9: 0 | AW9: 0 | AY9: 0 | BA9: 0 | BC9: 0 | BE9: 0 | BH9: =(V9-X9)-U9 -> -26306.05
B10: BNP_SCI MADELI | C10: 9-MADELI | D10: BNP | F10: 0 | G10: 1600000 | H10: 0.015 | I10: 43101 | K10: 119182.66 | L10: 1308116.2 | M10: 119182.66 | N10: 1207868 | O10: 119182.66 | P10: 1106105.6 | Q10: 119182.66 | R10: 1002806.3 | S10: 1012529.9 | T10: 0 | U10: 0 | V10: 0 | W10: 0 | X10: 0 | Y10: 0 | Z10: 0 | AA10: 0 | AB10: 0 | AC10: 0 | AD10: 0 | AE10: 0 | AG10: 0 | AI10: 0 | AK10: 0 | AM10: 0 | AO10: 0 | AQ10: 0 | AS10: 0 | AU10: 0 | AW10: 0 | AY10: 0 | BA10: 0 | BC10: 0 | BE10: 0 | BH10: =(V10-X10)-U10 -> 0
B11: CE_SCI ARAGO | C11: 9-ARAGO | D11: CE | F11: 0 | G11: 1350000 | H11: 0.0208 | I11: 42883 | K11: 52744.22 | L11: 1004352.9 | M11: 105809.52 | N11: 918619.65 | O11: 105809.52 | P11: 831086.06 | Q11: 105809.52 | R11: 741714.32 | S11: 105809.52 | T11: 650465.82 | U11: 655361.05 | V11: 0 | W11: 0 | X11: 0 | Y11: 0 | Z11: 0 | AA11: 0 | AB11: 0 | AC11: 0 | AD11: 0 | AE11: 0 | AG11: 0 | AI11: 0 | AK11: 0 | AM11: 0 | AO11: 0 | AQ11: 0 | AS11: 0 | AU11: 0 | AW11: 0 | AY11: 0 | BA11: 0 | BC11: 0 | BE11: 0 | BH11: =(V11-X11)-U11 -> -655361.05
B12: SG_SCI LEGRAND | C12: 9-LEGRAND | D12: SG | F12: 0 | G12: 780000 | H12: 0.0189 | I12: 43315 | K12: 59759.48 | L12: 668774.53 | M12: 59759.48 | N12: 621244.57 | O12: 59759.48 | P12: 572808.46 | Q12: 59759.48 | R12: 523448.94 | S12: 59759.48 | T12: 473148.4 | U12: 59759.48 | V12: 421888.91 | W12: 59759.48 | X12: 369652.17 | Y12: 59759.48 | Z12: 316419.56 | AA12: 59759.48 | AB12: 262172.09 | AC12: 59759.48 | AD12: 206890.42 | AE12: 59759.48 | AF12: 150155 | AG12: 59759.48 | AH12: 93145 | AI12: 59759.48 | AJ12: 34641 | AK12: 34641 | AL12: 0 | BH12: =(V12-X12)-U12 -> -7522.7425
B13: CA_SCI ORIENT | C13: 9-ORIENT | D13: CA | F13: 0 | G13: 665000 | H13: 0.014 | I13: 45021 | K13: 0 | L13: 0 | M13: 0 | N13: 0 | O13: 0 | P13: 0 | Q13: 36706.58 | R13: 634929.09 | S13: 49252.44 | T13: 594305.65 | U13: 49252.44 | V13: 553109.81 | W13: 49252.44 | X13: 511333.52 | Y13: 49252.44 | Z13: 468968.6 | AA13: 49252.44 | AB13: 426006.74 | AC13: 49252.44 | AD13: 382439.55 | AE13: 49252.44 | AF13: 338258 | AG13: 49252.44 | AH13: 293455 | AI13: 49252.44 | AJ13: 248020 | AK13: 49252.44 | AL13: 201945 | AM13: 49252.44 | AN13: 155221 | AO13: 49252.44 | AP13: 107838 | AQ13: 49252.44 | AR13: 59788 | AS13: 49252.44 | AT13: 11061 | AU13: 11061 | AV13: 0 | BD13: 0 | BF13: 0 | BH13: =(V13-X13)-U13 -> -7476.1501
B14: LCL_SCI ORIENT | C14: 9-ORIENT | D14: LCL | F14: 0 | G14: 377612 | H14: 0.018 | I14: 44964 | K14: 0 | L14: 0 | M14: 0 | N14: 0 | O14: 0 | P14: 0 | Q14: 27140.52 | R14: 356544.55 | S14: 29607.84 | T14: 333162.23 | U14: 29607.84 | V14: 309355.54 | W14: 29607.84 | X14: 285116.78 | Y14: 29607.84 | Z14: 260438.11 | AA14: 29607.84 | AB14: 235311.53 | AC14: 29607.84 | AD14: 209728.93 | AE14: 29607.84 | AF14: 183682 | AG14: 29607.84 | AH14: 157162 | AI14: 29607.84 | AJ14: 130161 | AK14: 29607.84 | AL14: 102670 | AM14: 29607.84 | AN14: 74680 | AO14: 29607.84 | AP14: 46183 | AQ14: 29607.84 | AR14: 17167 | AS14: 17167 | AU14: 0 | AW14: 0 | AY14: 0 | BA14: 0 | BC14: 0 | BE14: 0 | BH14: =(V14-X14)-U14 -> -5369.0794
B15: LCL_SCI CHENNEVIERES | C15: 9-CHENNEVIERES | D15: LCL | F15: 23925728 | G15: 734000 | H15: 0.046 | I15: 45227 | K15: 0 | L15: 0 | M15: 0 | N15: 0 | O15: 0 | P15: 0 | Q15: 8441 | R15: 734000 | S15: 43173.23 | T15: 724590.77 | U15: 71400.92 | V15: 685859.27 | W15: 71400.92 | X15: 645315.16 | Y15: 71400.92 | Z15: 602873.59 | AA15: 71400.92 | AB15: 558445.78 | AC15: 71400.92 | AD15: 511938.77 | AE15: 71400.92 | AF15: 463255 | AG15: 71400.92 | AH15: 412293 | AI15: 71400.92 | AJ15: 358946 | AK15: 71400.92 | AL15: 303103 | AM15: 71400.92 | AN15: 244646 | AO15: 71400.92 | AP15: 183453 | AQ15: 71400.92 | AR15: 119397 | AS15: 71400.92 | AT15: 52342 | AU15: 52342 | BH15: =(V15-X15)-U15 -> -30856.805
B16: CE_SCI TAVERNY | C16: 9-TAVERNY | D16: CE | F16: 0 | G16: 1408923 | H16: 0.0493 | I16: 45327 | K16: 0 | L16: 0 | M16: 0 | N16: 0 | O16: 0 | P16: 0 | Q16: 0 | R16: 0 | S16: 60388.392 | T16: 1401718.1 | U16: 112600.56 | V16: 1357225.9 | W16: 112600.56 | X16: 1310489.9 | Y16: 112600.56 | Z16: 1261397 | AA16: 116055.93 | AB16: 1206315.7 | AC16: 117207.72 | AD16: 1147256.8 | AE16: 117207.72 | AF16: 1085219 | AG16: 117207.72 | AH16: 1020054 | AI16: 117207.72 | AJ16: 951602 | AK16: 117207.72 | AL16: 879698 | AM16: 117207.72 | AN16: 804167 | AO16: 117207.72 | AP16: 724828 | AQ16: 117207.72 | AR16: 641488 | AS16: 117207.72 | AT16: 553945 | AU16: 117207.72 | AV16: 461988 | AW16: 117207.72 | AX16: 381824 | AY16: 117207.72 | AZ16: 263927 | BA16: 117207.72 | BB16: 157343 | BC16: 117207.72 | BD16: 45385 | BE16: 45385 | BH16: =(V16-X16)-U16 -> -65864.577
B17: CE_SCI CHATOU | C17: 9-GJB | D17: CE | F17: 0 | G17: 1200000 | H17: 0.051 | I17: 45163 | K17: 0 | L17: 0 | M17: 0 | N17: 0 | O17: 0 | P17: 0 | Q17: 25500 | R17: 1200000 | S17: 110173.67 | T17: 1149972.3 | U17: 114625.82 | V17: 1092667.8 | W17: 114625.82 | X17: 1032371.6 | Y17: 114625.82 | Z17: 968927.37 | AA17: 114625.82 | AB17: 902170.75 | AC17: 114625.82 | AD17: 831928.82 | AE17: 114625.82 | AF17: 758020 | AG17: 114625.82 | AH17: 680252 | AI17: 114625.82 | AJ17: 598424 | AK17: 114625.82 | AL17: 512323 | AM17: 114625.82 | AN17: 421728 | AO17: 114625.82 | AP17: 326402 | AQ17: 114625.82 | AR17: 226100 | AS17: 114625.82 | AT17: 120561 | AU17: 114625.82 | AV17: 9512 | AW17: 9512 | BH17: =(V17-X17)-U17 -> -54329.586
B18: LCL_SCI PLESSIS | C18: 9-GJB | D18: LCL | F18: 0 | G18: 740000 | H18: 0.046 | I18: 45503 | K18: 0 | L18: 0 | M18: 0 | N18: 0 | O18: 0 | P18: 0 | Q18: 0 | R18: 0 | S18: 34193.058 | T18: 722661.52 | U18: 68386.117 | V18: 686767.34 | W18: 68386.117 | X18: 649186.77 | Y18: 68386.117 | Z18: 609840.57 | AA18: 68386.117 | AB18: 568645.79 | AC18: 68386.117 | AD18: 525515.59 | AE18: 68386.117 | AF18: 480359 | AG18: 68386.117 | AH18: 433081 | AI18: 68386.117 | AJ18: 383582 | AK18: 68386.117 | AL18: 331757 | AM18: 68386.117 | AN18: 277497 | AO18: 68386.117 | AP18: 220688 | AQ18: 68386.117 | AR18: 161209 | AS18: 68386.117 | AT18: 98937 | AU18: 68386.117 | AV18: 33739 | AW18: 33739 | BH18: =(V18-X18)-U18 -> -30805.542
B19: SG_SCI ALFORTVILLE | C19: 9-CHENNEVIERES | D19: SG | F19: 223326101166 | G19: 840000 | H19: 0.0453 | I19: 45275 | K19: 0 | L19: 0 | M19: 0 | N19: 0 | O19: 0 | P19: 0 | Q19: 3171 | R19: 840000 | S19: 41642.1 | T19: 836409.9 | U19: 81133.2 | V19: 792256.82 | W19: 81133.2 | X19: 746061.56 | Y19: 81133.2 | Z19: 697729.65 | AA19: 81133.2 | AB19: 647162.27 | AC19: 81133.2 | AD19: 594256.02 | AE19: 81133.2 | AF19: 538903 | AG19: 81133.2 | AH19: 480989 | AI19: 81133.2 | AJ19: 420397 | AK19: 81133.2 | AL19: 357002 | AM19: 81133.2 | AN19: 290675 | AO19: 81133.2 | AP19: 221281 | AQ19: 81133.2 | AR19: 148677 | AS19: 81133.2 | AT19: 72714 | AU19: 72714 | BH19: =(V19-X19)-U19 -> -34937.935
B20: LCL_900k | C20: AXORIEL | D20: LCL | F20: 0 | G20: 900000 | H20: 0.012 | I20: 44742 | K20: 0 | L20: 0 | M20: 0 | N20: 0 | O20: 134432.12 | P20: 775996.98 | Q20: 134432.12 | R20: 650501.46 | S20: 134432.12 | T20: 523495.48 | U20: 134432.12 | V20: 394960.85 | W20: 134432.12 | X20: 264879.18 | Y20: 134432.12 | Z20: 133231.84 | AA20: 134031.23 | AB20: 0 | AC20: 0 | AD20: 0 | AE20: 0 | AF20: 0 | AG20: 0 | AH20: 0 | AI20: 0 | AJ20: 0 | AK20: 0 | AL20: 0 | AM20: 0 | AN20: 0 | AO20: 0 | AP20: 0 | AQ20: 0 | AR20: 0 | AS20: 0 | AT20: 0 | AU20: 0 | AV20: 0 | AW20: 0 | AX20: 0 | AY20: 0 | AZ20: 0 | BA20: 0 | BB20: 0 | BC20: 0 | BD20: 0 | BE20: 0 | BF20: 0 | BH20: =(V20-X20)-U20 -> -4350.4524
B21: LCL_900k | C21: HIO | D21: LCL | F21: 0 | G21: 900000 | H21: 0.012 | I21: 44742 | K21: 0 | L21: 0 | M21: 0 | N21: 0 | O21: 134432.12 | P21: 775996.98 | Q21: 134432.12 | R21: 650501.46 | S21: 134432.12 | T21: 523495.48 | U21: 134432.12 | V21: 394960.85 | W21: 134432.12 | X21: 264879.18 | Y21: 134432.12 | Z21: 133231.84 | AA21: 134031.23 | AB21: 0 | AC21: 0 | AD21: 0 | AE21: 0 | AF21: 0 | AG21: 0 | AH21: 0 | AI21: 0 | AJ21: 0 | AK21: 0 | AL21: 0 | AM21: 0 | AN21: 0 | AO21: 0 | AP21: 0 | AQ21: 0 | AR21: 0 | AS21: 0 | AT21: 0 | AU21: 0 | AV21: 0 | AW21: 0 | AX21: 0 | AY21: 0 | AZ21: 0 | BA21: 0 | BB21: 0 | BC21: 0 | BD21: 0 | BE21: 0 | BF21: 0 | BH21: =(V21-X21)-U21 -> -4350.4524
B22: BNP_793k | C22: AXORIEL | D22: BNP | F22: 0 | G22: 793000 | H22: 0.00781 | I22: 43637 | K22: 120019.13 | L22: 679714.29 | M22: 119134.36 | N22: 566428.59 | O22: 119457.23 | P22: 453142.89 | Q22: 130182.54 | R22: 339857.18 | S22: 128413.04 | T22: 226571.5 | U22: 122954.35 | V22: 113285.79 | W22: 117674.14 | X22: 0 | Y22: 0 | Z22: 0 | AA22: 0 | AB22: 0 | AC22: 0 | AD22: 0 | AE22: 0 | AF22: 0 | AG22: 0 | AH22: 0 | AI22: 0 | AJ22: 0 | AK22: 0 | AL22: 0 | AM22: 0 | AN22: 0 | AO22: 0 | AP22: 0 | AQ22: 0 | AR22: 0 | AS22: 0 | AT22: 0 | AU22: 0 | AV22: 0 | AW22: 0 | AX22: 0 | AY22: 0 | AZ22: 0 | BA22: 0 | BB22: 0 | BC22: 0 | BD22: 0 | BE22: 0 | BF22: 0 | BH22: =(V22-X22)-U22 -> -9668.5641
B23: BNP_793k | C23: HIO | D23: BNP | F23: 0 | G23: 793000 | H23: 0.00781 | I23: 43637 | K23: 120019.13 | L23: 679714.29 | M23: 119134.36 | N23: 566428.59 | O23: 119457.23 | P23: 453142.89 | Q23: 130182.54 | R23: 339857.18 | S23: 128413.04 | T23: 226571.5 | U23: 122954.35 | V23: 113285.79 | W23: 117674.14 | X23: 0 | Y23: 0 | Z23: 0 | AA23: 0 | AB23: 0 | AC23: 0 | AD23: 0 | AE23: 0 | AF23: 0 | AG23: 0 | AH23: 0 | AI23: 0 | AJ23: 0 | AK23: 0 | AL23: 0 | AM23: 0 | AN23: 0 | AO23: 0 | AP23: 0 | AQ23: 0 | AR23: 0 | AS23: 0 | AT23: 0 | AU23: 0 | AV23: 0 | AW23: 0 | AX23: 0 | AY23: 0 | AZ23: 0 | BA23: 0 | BB23: 0 | BC23: 0 | BD23: 0 | BE23: 0 | BF23: 0 | BH23: =(V23-X23)-U23 -> -9668.5641
G24: 16030513 | K24: 493718.33 | L24: 4932847.6 | M24: 588728 | N24: 4413963.3 | O24: 922288.39 | P24: 7312940.8 | Q24: 1132575 | R24: 10171203 | S24: 2289541.8 | T24: 10353884 | U24: 2312745.3 | V24: 8710696.1 | W24: 1305258.4 | X24: 7689411.4 | Y24: 1064688.7 | Z24: 6879980.4 | AA24: 1067342.3 | AB24: 6046390.8 | AC24: 800431.65 | AD24: 5459707.2 | AE24: 800431.65 | AF24: 5459707.2 | AG24: 800431.65 | AH24: 5459707.2 | AI24: 800431.65 | AJ24: 5459707.2 | AK24: 800431.65 | AL24: 5459707.2 | AM24: 800431.65 | AN24: 5459707.2 | AO24: 800431.65 | AP24: 5459707.2 | AQ24: 800431.65 | AR24: 5459707.2 | AS24: 800431.65 | AT24: 5459707.2 | AU24: 800431.65 | AV24: 5459707.2 | AW24: 800431.65 | AX24: 5459707.2 | AY24: 800431.65 | AZ24: 5459707.2 | BA24: 800431.65 | BB24: 5459707.2 | BC24: 800431.65 | BD24: 5459707.2 | BE24: 800431.65 | BF24: 5459707.2 | BH24: =(V24-X24)-U24 -> -1291460.5
